Workbook

Sheet CALENDARIO 2020
B1: CALENDARIO 2020
B2: 43831
C3: Mi | D3: Ju | E3: Vi | F3: Sá | G3: Do | H3: Lu | I3: Ma | J3: Mi | K3: Ju | L3: Vi | M3: Sá | N3: Do | O3: Lu | P3: Ma | Q3: Mi | R3: Ju | S3: Vi | T3: Sá | U3: Do | V3: Lu | W3: Ma | X3: Mi | Y3: Ju | Z3: Vi | AA3: Sá | AB3: Do | AC3: Lu | AD3: Ma | AE3: Mi | AF3: Ju | AG3: Vi
B4: VANE1 | C4: 1 | D4: 2 | E4: 3 | F4: 4 | G4: 5 | H4: 6 | I4: 7 | J4: 8 | K4: 9 | L4: 10 | M4: 11 | N4: 12 | O4: 13 | P4: 14 | Q4: 15 | R4: 16 | S4: 17 | T4: 18 | U4: 19 | V4: V | W4: 21 | X4: 22 | Y4: 23 | Z4: 24 | AA4: 25 | AB4: 26 | AC4: V | AD4: 28 | AE4: 29 | AF4: 30 | AG4: 31
B5: VANE2 | C5: 1 | D5: V | E5: V | F5: 4 | G5: 5 | H5: 6 | I5: V | J5: 8 | K5: 9 | L5: 10 | M5: 11 | N5: 12 | O5: 13 | P5: 14 | Q5: 15 | R5: 16 | S5: 17 | T5: 18 | U5: 19 | V5: 20 | W5: 21 | X5: 22 | Y5: 23 | Z5: 24 | AA5: 25 | AB5: 26 | AC5: 27 | AD5: 28 | AE5: 29 | AF5: 30 | AG5: 31
B6: ISRA | C6: 1 | D6: P | E6: P | F6: 4 | G6: 5 | H6: 6 | I6: P | J6: P | K6: P | L6: LDP | M6: 11 | N6: 12 | O6: 13 | P6: 14 | Q6: G | R6: G | S6: G | T6: G | U6: G | V6: G | W6: G | X6: 22 | Y6: 23 | Z6: 24 | AA6: 25 | AB6: 26 | AC6: 27 | AD6: 28 | AE6: 29 | AF6: 30 | AG6: 31
B7: CHEMA | C7: 1 | D7: V | E7: V | F7: 4 | G7: 5 | H7: 6 | I7: 7 | J7: G | K7: G | L7: G | M7: G | N7: G | O7: G | P7: G | Q7: 15 | R7: 16 | S7: 17 | T7: 18 | U7: 19 | V7: 20 | W7: 21 | X7: 22 | Y7: 23 | Z7: 24 | AA7: 25 | AB7: 26 | AC7: 27 | AD7: 28 | AE7: G | AF7: G | AG7: G
B8: FERNANDO LANGREO | C8: 1 | D8: 2 | E8: 3 | F8: 4 | G8: 5 | H8: 6 | I8: 7 | J8: 8 | K8: 9 | L8: 10 | M8: 11 | N8: 12 | O8: 13 | P8: 14 | Q8: 15 | R8: 16 | S8: T | T8: 18 | U8: 19 | V8: 20 | W8: 21 | X8: 22 | Y8: 23 | Z8: 24 | AA8: 25 | AB8: 26 | AC8: 27 | AD8: 28 | AE8: 29 | AF8: 30 | AG8: T
B9: DANI | C9: 1 | D9: 2 | E9: 3 | F9: 4 | G9: 5 | H9: 6 | I9: V | J9: 8 | K9: 9 | L9: 10 | M9: 11 | N9: 12 | O9: 13 | P9: 14 | Q9: 15 | R9: 16 | S9: 17 | T9: 18 | U9: 19 | V9: 20 | W9: 21 | X9: 22 | Y9: 23 | Z9: 24 | AA9: 25 | AB9: 26 | AC9: 27 | AD9: 28 | AE9: 29 | AF9: 30 | AG9: 31
B10: FERNANDO RUBIO | C10: 1 | D10: V | E10: V | F10: 4 | G10: 5 | H10: 6 | I10: 7 | J10: 8 | K10: 9 | L10: 10 | M10: 11 | N10: 12 | O10: 13 | P10: 14 | Q10: 15 | R10: 16 | S10: 17 | T10: 18 | U10: 19 | V10: 20 | W10: 21 | X10: 22 | Y10: 23 | Z10: 24 | AA10: 25 | AB10: 26 | AC10: 27 | AD10: 28 | AE10: 29 | AF10: 30 | AG10: 31
B11: JORGE AMARILLAS | C11: G | D11: G | E11: G | F11: G | G11: G | H11: G | I11: G | J11: 8 | K11: 9 | L11: 10 | M11: 11 | N11: 12 | O11: 13 | P11: 14 | Q11: 15 | R11: 16 | S11: 17 | T11: 18 | U11: 19 | V11: V | W11: V | X11: G | Y11: G | Z11: G | AA11: G | AB11: G | AC11: G | AD11: G | AE11: 29 | AF11: 30 | AG11: 31
B12: EDUARDO | C12: 1 | D12: V | E12: V | F12: 4 | G12: 5 | H12: 6 | I12: 7 | J12: 8 | K12: 9 | L12: 10 | M12: 11 | N12: 12 | O12: 13 | P12: 14 | Q12: 15 | R12: 16 | S12: 17 | T12: 18 | U12: 19 | V12: 20 | W12: 21 | X12: 22 | Y12: 23 | Z12: T | AA12: 25 | AB12: 26 | AC12: 27 | AD12: 28 | AE12: 29 | AF12: V | AG12: 31
B14: 43862
C15: Sá | D15: Do | E15: Lu | F15: Ma | G15: Mi | H15: Ju | I15: Vi | J15: Sá | K15: Do | L15: Lu | M15: Ma | N15: Mi | O15: Ju | P15: Vi | Q15: Sá | R15: Do | S15: Lu | T15: Ma | U15: Mi | V15: Ju | W15: Vi | X15: Sá | Y15: Do | Z15: Lu | AA15: Ma | AB15: Mi | AC15: Ju | AD15: Vi | AE15: Sá
B16: VANE 1 | C16: 1 | D16: 2 | E16: 3 | F16: 4 | G16: 5 | H16: 6 | I16: 7 | J16: 8 | K16: 9 | L16: V | M16: V | N16: 12 | O16: 13 | P16: 14 | Q16: 15 | R16: 16 | S16: 17 | T16: 18 | U16: 19 | V16: 20 | W16: 21 | X16: 22 | Y16: 23 | Z16: 24 | AA16: 25 | AB16: 26 | AC16: 27 | AD16: 28 | AE16: 29
B17: VANE 2 | C17: 1 | D17: 2 | E17: V | F17: 4 | G17: 5 | H17: 6 | I17: 7 | J17: 8 | K17: 9 | L17: 10 | M17: 11 | N17: 12 | O17: 13 | P17: 14 | Q17: 15 | R17: 16 | S17: 17 | T17: V | U17: 19 | V17: 20 | W17: 21 | X17: 22 | Y17: 23 | Z17: 24 | AA17: 25 | AB17: 26 | AC17: 27 | AD17: 28 | AE17: 29
B18: ISRAEL HURTADO | C18: 1 | D18: 2 | E18: 3 | F18: 4 | G18: G | H18: G | I18: G | J18: G | K18: G | L18: G | M18: G | N18: 12 | O18: 13 | P18: 14 | Q18: 15 | R18: 16 | S18: 17 | T18: 18 | U18: 19 | V18: 20 | W18: 21 | X18: 22 | Y18: 23 | Z18: 24 | AA18: 25 | AB18: G | AC18: G | AD18: G | AE18: G
B19: CHEMA | C19: G | D19: G | E19: G | F19: G | G19: 5 | H19: 6 | I19: 7 | J19: 8 | K19: 9 | L19: 10 | M19: 11 | N19: 12 | O19: 13 | P19: 14 | Q19: 15 | R19: 16 | S19: 17 | T19: 18 | U19: G | V19: G | W19: G | X19: G | Y19: G | Z19: G | AA19: G | AB19: 26 | AC19: 27 | AD19: 28 | AE19: 29
B20: FERNANDO LANGREO | C20: 1 | D20: 2 | E20: 3 | F20: 4 | G20: 5 | H20: 6 | I20: 7 | J20: 8 | K20: 9 | L20: 10 | M20: 11 | N20: 12 | O20: 13 | P20: T | Q20: 15 | R20: 16 | S20: 17 | T20: 18 | U20: 19 | V20: 20 | W20: 21 | X20: 22 | Y20: 23 | Z20: 24 | AA20: 25 | AB20: 26 | AC20: 27 | AD20: T | AE20: 29
B21: DANI | C21: 1 | D21: 2 | E21: 3 | F21: 4 | G21: 5 | H21: 6 | I21: V | J21: 8 | K21: 9 | L21: 10 | M21: 11 | N21: 12 | O21: 13 | P21: 14 | Q21: 15 | R21: 16 | S21: 17 | T21: 18 | U21: 19 | V21: 20 | W21: 21 | X21: 22 | Y21: 23 | Z21: 24 | AA21: 25 | AB21: 26 | AC21: 27 | AD21: 28 | AE21: 29
B22: FERNANDO RUBIO | C22: 1 | D22: 2 | E22: 3 | F22: 4 | G22: 5 | H22: 6 | I22: 7 | J22: 8 | K22: 9 | L22: 10 | M22: 11 | N22: 12 | O22: 13 | P22: 14 | Q22: 15 | R22: 16 | S22: 17 | T22: 18 | U22: 19 | V22: 20 | W22: 21 | X22: 22 | Y22: 23 | Z22: 24 | AA22: 25 | AB22: 26 | AC22: 27 | AD22: 28 | AE22: 29
B23: JORGE AMARILLAS | C23: 1 | D23: 2 | E23: 3 | F23: 4 | G23: 5 | H23: 6 | I23: 7 | J23: 8 | K23: 9 | L23: 10 | M23: 11 | N23: G | O23: G | P23: G | Q23: G | R23: G | S23: G | T23: G | U23: 19 | V23: 20 | W23: 21 | X23: 22 | Y23: 23 | Z23: 24 | AA23: 25 | AB23: 26 | AC23: 27 | AD23: 28 | AE23: 29
B24: EDUARDO | C24: 1 | D24: 2 | E24: 3 | F24: 4 | G24: 5 | H24: 6 | I24: T | J24: 8 | K24: 9 | L24: 10 | M24: 11 | N24: 12 | O24: 13 | P24: 14 | Q24: 15 | R24: 16 | S24: 17 | T24: 18 | U24: 19 | V24: 20 | W24: T | X24: 22 | Y24: 23 | Z24: 24 | AA24: 25 | AB24: 26 | AC24: 27 | AD24: 28 | AE24: 29
B26: 43891
C27: Do | D27: Lu | E27: Ma | F27: Mi | G27: Ju | H27: Vi | I27: Sá | J27: Do | K27: Lu | L27: Ma | M27: Mi | N27: Ju | O27: Vi | P27: Sá | Q27: Do | R27: Lu | S27: Ma | T27: Mi | U27: Ju | V27: Vi | W27: Sá | X27: Do | Y27: Lu | Z27: Ma | AA27: Mi | AB27: Ju | AC27: Vi | AD27: Sá | AE27: Do | AF27: Lu | AG27: Ma
B28: VANE 1 | C28: 1 | D28: 2 | E28: 3 | F28: 4 | G28: 5 | H28: 6 | I28: 7 | J28: 8 | K28: 9 | L28: 10 | M28: 11 | N28: 12 | O28: 13 | P28: 14 | Q28: 15 | R28: 16 | S28: 17 | T28: 18 | U28: 19 | V28: 20 | W28: 21 | X28: 22 | Y28: 23 | Z28: 24 | AA28: 25 | AB28: 26 | AC28: 27 | AD28: 28 | AE28: 29 | AF28: 30 | AG28: 31
B29: VANE 2 | C29: 1 | D29: 2 | E29: 3 | F29: 4 | G29: 5 | H29: 6 | I29: 7 | J29: 8 | K29: 9 | L29: 10 | M29: 11 | N29: 12 | O29: 13 | P29: 14 | Q29: 15 | R29: 16 | S29: 17 | T29: 18 | U29: 19 | V29: 20 | W29: 21 | X29: 22 | Y29: 23 | Z29: 24 | AA29: 25 | AB29: 26 | AC29: 27 | AD29: 28 | AE29: 29 | AF29: 30 | AG29: 31
B30: ISRAEL HURTADO | C30: G | D30: G | E30: G | F30: 4 | G30: 5 | H30: 6 | I30: 7 | J30: 8 | K30: 9 | L30: 10 | M30: 11 | N30: 12 | O30: 13 | P30: 14 | Q30: 15 | R30: 16 | S30: 17 | T30: G | U30: G | V30: G | W30: G | X30: G | Y30: G | Z30: G | AA30: 25 | AB30: 26 | AC30: 27 | AD30: 28 | AE30: 29 | AF30: 30 | AG30: 31
B31: CHEMA | C31: 1 | D31: 2 | E31: 3 | F31: 4 | G31: 5 | H31: 6 | I31: 7 | J31: 8 | K31: 9 | L31: 10 | M31: G | N31: G | O31: G | P31: G | Q31: G | R31: G | S31: G | T31: 18 | U31: 19 | V31: 20 | W31: 21 | X31: 22 | Y31: 23 | Z31: 24 | AA31: 25 | AB31: 26 | AC31: 27 | AD31: 28 | AE31: 29 | AF31: 30 | AG31: 31
B32: FERNANDO LANGREO | C32: 1 | D32: 2 | E32: 3 | F32: 4 | G32: 5 | H32: 6 | I32: 7 | J32: 8 | K32: 9 | L32: 10 | M32: 11 | N32: 12 | O32: T | P32: 14 | Q32: 15 | R32: 16 | S32: 17 | T32: 18 | U32: 19 | V32: 20 | W32: 21 | X32: 22 | Y32: 23 | Z32: 24 | AA32: 25 | AB32: 26 | AC32: T | AD32: 28 | AE32: 29 | AF32: 30 | AG32: 31
B33: DANI | C33: 1 | D33: 2 | E33: 3 | F33: 4 | G33: 5 | H33: 6 | I33: 7 | J33: 8 | K33: 9 | L33: 10 | M33: 11 | N33: 12 | O33: 13 | P33: 14 | Q33: 15 | R33: 16 | S33: 17 | T33: 18 | U33: 19 | V33: 20 | W33: 21 | X33: 22 | Y33: 23 | Z33: 24 | AA33: 25 | AB33: 26 | AC33: 27 | AD33: 28 | AE33: 29 | AF33: 30 | AG33: 31
B34: FERNANDO RUBIO | C34: 1 | D34: 2 | E34: 3 | F34: 4 | G34: 5 | H34: 6 | I34: 7 | J34: 8 | K34: 9 | L34: 10 | M34: 11 | N34: 12 | O34: 13 | P34: 14 | Q34: 15 | R34: 16 | S34: 17 | T34: 18 | U34: 19 | V34: 20 | W34: 21 | X34: 22 | Y34: 23 | Z34: 24 | AA34: 25 | AB34: 26 | AC34: 27 | AD34: 28 | AE34: 29 | AF34: 30 | AG34: 31
B35: JORGE AMARILLAS | C35: 1 | D35: 2 | E35: 3 | F35: G | G35: G | H35: G | I35: G | J35: G | K35: G | L35: G | M35: 11 | N35: 12 | O35: 13 | P35: 14 | Q35: 15 | R35: 16 | S35: 17 | T35: 18 | U35: 19 | V35: 20 | W35: 21 | X35: 22 | Y35: 23 | Z35: 24 | AA35: G | AB35: G | AC35: G | AD35: G | AE35: G | AF35: G | AG35: G
B36: EDUARDO | C36: 1 | D36: 2 | E36: 3 | F36: 4 | G36: 5 | H36: T | I36: 7 | J36: 8 | K36: 9 | L36: 10 | M36: 11 | N36: 12 | O36: 13 | P36: 14 | Q36: 15 | R36: 16 | S36: 17 | T36: 18 | U36: 19 | V36: T | W36: 21 | X36: 22 | Y36: 23 | Z36: 24 | AA36: 25 | AB36: 26 | AC36: 27 | AD36: 28 | AE36: 29 | AF36: 30 | AG36: 31
B38: 43922
C39: Mi | D39: Ju | E39: Vi | F39: Sá | G39: Do | H39: Lu | I39: Ma | J39: Mi | K39: Ju | L39: Vi | M39: Sá | N39: Do | O39: Lu | P39: Ma | Q39: Mi | R39: Ju | S39: Vi | T39: Sá | U39: Do | V39: Lu | W39: Ma | X39: Mi | Y39: Ju | Z39: Vi | AA39: Sá | AB39: Do | AC39: Lu | AD39: Ma | AE39: Mi | AF39: Ju
B40: VANE1 | C40: 1 | D40: 2 | E40: 3 | F40: 4 | G40: 5 | H40: 6 | I40: 7 | J40: 8 | K40: 9 | L40: 10 | M40: 11 | N40: 12 | O40: 13 | P40: 14 | Q40: 15 | R40: 16 | S40: 17 | T40: 18 | U40: 19 | V40: 20 | W40: 21 | X40: 22 | Y40: 23 | Z40: 24 | AA40: 25 | AB40: 26 | AC40: 27 | AD40: 28 | AE40: V | AF40: V
B41: VANE2 | C41: 1 | D41: 2 | E41: 3 | F41: 4 | G41: 5 | H41: 6 | I41: 7 | J41: 8 | K41: 9 | L41: 10 | M41: 11 | N41: 12 | O41: 13 | P41: 14 | Q41: 15 | R41: 16 | S41: 17 | T41: 18 | U41: 19 | V41: 20 | W41: 21 | X41: 22 | Y41: 23 | Z41: 24 | AA41: 25 | AB41: 26 | AC41: 27 | AD41: 28 | AE41: 29 | AF41: 30
B42: ISRA | C42: G | D42: G | E42: G | F42: G | G42: G | H42: G | I42: G | J42: 8 | K42: 9 | L42: 10 | M42: 11 | N42: 12 | O42: 13 | P42: 14 | Q42: 15 | R42: 16 | S42: 17 | T42: 18 | U42: 19 | V42: 20 | W42: 21 | X42: G | Y42: G | Z42: G | AA42: G | AB42: G | AC42: G | AD42: G | AE42: 29 | AF42: 30
B43: CHEMA | C43: 1 | D43: 2 | E43: 3 | F43: 4 | G43: 5 | H43: 6 | I43: 7 | J43: G | K43: G | L43: G | M43: G | N43: G | O43: G | P43: G | Q43: 15 | R43: 16 | S43: 17 | T43: 18 | U43: 19 | V43: 20 | W43: 21 | X43: 22 | Y43: 23 | Z43: 24 | AA43: 25 | AB43: 26 | AC43: 27 | AD43: 28 | AE43: 29 | AF43: 30
...

Sheet Guardias Voz
A1: Nombre | B1: Area | C1: Mes | D1: 42491 | E1: 42492 | F1: 42493 | G1: 42494 | H1: 42495 | I1: 42496 | J1: 42497 | K1: 42498 | L1: 42499 | M1: 42500 | N1: 42501 | O1: 42502 | P1: 42503 | Q1: 42504 | R1: 42505 | S1: 42506 | T1: 42507 | U1: 42508 | V1: 42509 | W1: 42510 | X1: 42511 | Y1: 42512 | Z1: 42513 | AA1: 42514 | AB1: 42515 | AC1: 42516 | AD1: 42517 | AE1: 42518 | AF1: 42519 | AG1: 42520 | AH1: 42521
A2: Javier Puertas de la Plaza | B2: Voz | C2: Enero 2025 | D2: G | E2: G | F2: G | T2: G | U2: G | V2: G | W2: G | X2: G | Y2: G | Z2: G | AH2: G | AJ2: VP | AK2: Vacaciones Pasadas (Año Anterior)
A3: José María Moreno Moreno | B3: Voz | C3: Enero 2025 | E3: VP | F3: VP | J3: VP | K3: VP | M3: G | N3: G | O3: G | P3: G | Q3: G | R3: G | S3: G | AJ3: V | AK3: Vacaciones
A4: Alfonso Gomez Calzado | B4: Voz | C4: Enero 2025 | E4: VP | F4: VP | G4: G | H4: G | I4: G | J4: G | K4: G | L4: G | AA4: G | AB4: G | AC4: G | AD4: G | AE4: G | AF4: G | AG4: G | AJ4: C | AK4: Convenio
A5: Javier Puertas de la Plaza | B5: Voz | C5: Febrero 2025 | D5: G | E5: G | F5: G | G5: G | H5: G | I5: G | L5: X | M5: X | N5: X | O5: X | P5: X | Q5: X | AE5: G | AJ5: X | AK5: Viaje
A6: José María Moreno Moreno | B6: Voz | C6: Febrero 2025 | J6: G | K6: G | L6: G | M6: G | N6: G | O6: G | P6: G | X6: G | Y6: G | Z6: G | AA6: G | AB6: G | AC6: G | AD6: G | AJ6: G | AK6: Guardia
A7: Alfonso Gomez Calzado | B7: Voz | C7: Febrero 2025 | Q7: G | R7: G | S7: G | T7: G | U7: G | V7: G | W7: G | AD7: V | AE7: V
A8: Javier Puertas de la Plaza | B8: Voz | C8: Marzo 2025 | D8: G | E8: G | F8: G | G8: G | H8: G | I8: G | X8: G | Y8: G | Z8: G | AA8: G | AB8: G | AC8: G | AD8: G | AJ8: Fichero Oficial de Vacaciones 2025
A9: José María Moreno Moreno | B9: Voz | C9: Marzo 2025 | Q9: G | R9: G | S9: G | T9: G | U9: G | V9: G | W9: G | AJ9: Turnos Teletrabajo Voz 2025
A10: Alfonso Gomez Calzado | B10: Voz | C10: Marzo 2025 | J10: G | K10: G | L10: G | M10: G | N10: G | O10: G | P10: G | AE10: G | AF10: G | AG10: G | AH10: G
A11: Javier Puertas de la Plaza | B11: Voz | C11: Abril 2025 | N11: G | O11: G | P11: G | Q11: V | R11: V | S11: V | T11: G
A12: José María Moreno Moreno | B12: Voz | C12: Abril 2025 | G12: G | H12: G | I12: G | J12: G | K12: G | L12: G | M12: G | U12: G | V12: G | W12: G | X12: G | Y12: G | Z12: G | AA12: G
A13: Alfonso Gomez Calzado | B13: Voz | C13: Abril 2025 | D13: G | E13: G | F13: G | Q13: V | R13: V | S13: V | AB13: G | AC13: G | AD13: G | AE13: G | AF13: G | AG13: G
A14: Javier Puertas de la Plaza | B14: Voz | C14: Mayo 2025 | E14: G | F14: G | G14: G | H14: G | I14: G | J14: G | K14: G | Z14: G | AA14: G | AB14: G | AC14: G | AD14: G | AE14: G | AF14: G
A15: José María Moreno Moreno | B15: Voz | C15: Mayo 2025 | S15: G | T15: G | U15: G | V15: G | W15: G | X15: G | Y15: G
A16: Alfonso Gomez Calzado | B16: Voz | C16: Mayo 2025 | D16: G | L16: G | M16: G | N16: G | O16: G | P16: G | Q16: G | R16: G | AG16: G | AH16: G
A17: Javier Puertas de la Plaza | B17: Voz | C17: Junio 2025 | P17: G | Q17: G | R17: G | S17: G | T17: G | U17: G | V17: G
A18: José María Moreno Moreno | B18: Voz | C18: Junio 2025 | I18: G | J18: G | K18: G | L18: G | M18: G | N18: G | O18: G | AD18: G | AE18: G | AF18: G | AG18: G
A19: Alfonso Gomez Calzado | B19: Voz | C19: Junio 2025 | D19: G | E19: G | F19: G | G19: G | H19: G | W19: G | X19: G | Y19: G | Z19: G | AA19: G | AB19: G | AC19: G
A20: Javier Puertas de la Plaza | B20: Voz | C20: Julio 2025 | G20: G | H20: G | I20: G | J20: G | K20: G | L20: G | M20: G | Q20: V | R20: V | S20: V | T20: V | U20: V | X20: V | Y20: V | Z20: V | AA20: V | AE20: V | AF20: V | AG20: V | AH20: V
A21: José María Moreno Moreno | B21: Voz | C21: Julio 2025 | D21: G | E21: G | F21: G | U21: G | V21: G | W21: G | X21: G | Y21: G | Z21: G | AA21: G
A22: Alfonso Gomez Calzado | B22: Voz | C22: Julio 2025 | N22: G | O22: G | P22: G | Q22: G | R22: G | S22: G | T22: G | AB22: G | AC22: G | AD22: G | AE22: G | AF22: G | AG22: G | AH22: G
A23: Javier Puertas de la Plaza | B23: Voz | C23: Agosto 2025 | D23: G | E23: G | F23: G | G23: G | H23: G | I23: G | J23: G | R23: G | S23: G | T23: G | U23: G | V23: G | W23: G | X23: G
A24: José María Moreno Moreno | B24: Voz | C24: Agosto 2025 | K24: G | L24: G | M24: G | N24: G | O24: G | P24: G | Q24: G | AF24: G | AG24: G | AH24: G
A25: Alfonso Gomez Calzado | B25: Voz | C25: Agosto 2025 | G25: V | H25: V | I25: V | J25: V | K25: V | N25: V | O25: V | P25: V | Q25: V | Y25: G | Z25: G | AA25: G | AB25: G | AC25: G | AD25: G | AE25: G
A26: Javier Puertas de la Plaza | B26: Voz | C26: Septiembre 2025 | H26: G | I26: G | J26: G | K26: G | L26: G | M26: G | N26: G | AC26: V | AD26: G | AE26: G | AF26: G | AG26: G | AJ26: Cambiar guardia JP
A27: José María Moreno Moreno | B27: Voz | C27: Septiembre 2025 | D27: G | E27: G | F27: G | G27: G | V27: G | W27: G | X27: G | Y27: G | Z27: G | AA27: G | AB27: G
A28: Alfonso Gomez Calzado | B28: Voz | C28: Septiembre 2025 | O28: G | P28: G | Q28: G | R28: G | S28: G | T28: G | U28: G
A29: Javier Puertas de la Plaza | B29: Voz | C29: Octubre 2025 | D29: G | E29: G | T29: G | U29: G | V29: G | W29: G | X29: G | Y29: G | Z29: G
A30: José María Moreno Moreno | B30: Voz | C30: Octubre 2025 | M30: G | N30: G | O30: G | P30: G | Q30: G | R30: G | S30: G | AH30: G
A31: Alfonso Gomez Calzado | B31: Voz | C31: Octubre 2025 | F31: G | G31: G | H31: G | I31: G | J31: G | K31: G | L31: G | AA31: G | AB31: G | AC31: G | AD31: G | AE31: G | AF31: G | AG31: G
A32: Javier Puertas de la Plaza | B32: Voz | C32: Noviembre 2025 | J32: G | K32: G | L32: G | M32: G | N32: G | O32: G | P32: G | AE32: G | AF32: G | AG32: G
A33: José María Moreno Moreno | B33: Voz | C33: Noviembre 2025 | D33: G | E33: G | F33: G | G33: G | H33: G | I33: G | X33: G | Y33: G | Z33: G | AA33: G | AB33: G | AC33: G | AD33: G
A34: Alfonso Gomez Calzado | B34: Voz | C34: Noviembre 2025 | Q34: G | R34: G | S34: G | T34: G | U34: G | V34: G | W34: G | AA34: V | AB34: V | AC34: V | AD34: V | AE34: V
A35: Javier Puertas de la Plaza | B35: Voz | C35: Diciembre 2025 | D35: G | E35: G | F35: G | G35: G | V35: G | W35: G | X35: G | Y35: G | Z35: G | AA35: G | AB35: G
A36: José María Moreno Moreno | B36: Voz | C36: Diciembre 2025 | O36: G | P36: G | Q36: G | R36: G | S36: G | T36: G | U36: G
A37: Alfonso Gomez Calzado | B37: Voz | C37: Diciembre 2025 | H37: G | I37: G | J37: G | K37: G | L37: G | M37: G | N37: G | AC37: G | AD37: G | AE37: G | AF37: G | AG37: G | AH37: G
A38: Javier Puertas de la Plaza | B38: Voz | C38: Enero 2026 | E38: V | H38: V | J38: V | L38: G | M38: G | N38: G | O38: G | P38: G | Q38: G | R38: G | AG38: G | AH38: G
A39: José María Moreno Moreno | B39: Voz | C39: Enero 2026 | E39: G | F39: G | G39: G | H39: G | I39: G | J39: G | K39: G | Z39: G | AA39: G | AB39: G | AC39: G | AD39: G | AE39: G | AF39: G
A40: Alfonso Gomez Calzado | B40: Voz | C40: Enero 2026 | D40: G | E40: V | H40: V | J40: V | K40: V | L40: V | S40: G | T40: G | U40: G | V40: G | W40: G | X40: G | Y40: G
...

Sheet Guardias Internos Network
B2: 45658 | AI2: Fichero Oficial de Vacaciones 2025
C3: Mi | D3: Ju | E3: Vi | F3: Sá | G3: Do | H3: Lu | I3: Ma | J3: Mi | K3: Ju | L3: Vi | M3: Sá | N3: Do | O3: Lu | P3: Ma | Q3: Mi | R3: Ju | S3: Vi | T3: Sá | U3: Do | V3: Lu | W3: Ma | X3: Mi | Y3: Ju | Z3: Vi | AA3: Sá | AB3: Do | AC3: Lu | AD3: Ma | AE3: Mi | AF3: Ju | AG3: Vi
B4: JORGE | C4: 1 | D4: 2 | E4: 3 | F4: 4 | G4: 5 | H4: 6 | I4: 7 | J4: 8 | K4: 9 | L4: 10 | M4: 11 | N4: 12 | O4: 13 | P4: 14 | Q4: 15 | R4: 16 | S4: 17 | T4: 18 | U4: 19 | V4: 20 | W4: 21 | X4: 22 | Y4: V | Z4: V | AA4: 25 | AB4: 26 | AC4: V | AD4: V | AE4: V | AF4: V | AG4: V
B5: ISRAEL HURTADO | C5: 1 | D5: V | E5: V | F5: 4 | G5: 5 | H5: 6 | I5: V | J5: V | K5: V | L5: V | M5: 11 | N5: 12 | O5: 13 | P5: 14 | Q5: G | R5: G | S5: G | T5: G | U5: G | V5: G | W5: G | X5: 22 | Y5: V | Z5: 24 | AA5: 25 | AB5: 26 | AC5: 27 | AD5: 28 | AE5: 29 | AF5: 30 | AG5: V
B6: CHEMA | C6: 1 | D6: 2 | E6: 3 | F6: 4 | G6: 5 | H6: 6 | I6: 7 | J6: 8 | K6: 9 | L6: 10 | M6: 11 | N6: 12 | O6: 13 | P6: 14 | Q6: 15 | R6: 16 | S6: 17 | T6: 18 | U6: 19 | V6: 20 | W6: 21 | X6: G | Y6: G | Z6: G | AA6: G | AB6: G | AC6: G | AD6: G | AE6: 29 | AF6: 30 | AG6: 31
B7: DANI | C7: G | D7: G | E7: G | F7: G | G7: G | H7: G | I7: G | J7: 8 | K7: 9 | L7: 10 | M7: 11 | N7: 12 | O7: 13 | P7: 14 | Q7: 15 | R7: 16 | S7: 17 | T7: 18 | U7: 19 | V7: 20 | W7: 21 | X7: 22 | Y7: 23 | Z7: 24 | AA7: 25 | AB7: 26 | AC7: 27 | AD7: 28 | AE7: 29 | AF7: 30 | AG7: 31
B8: EDUARDO | C8: 1 | D8: V | E8: V | F8: 4 | G8: 5 | H8: 6 | I8: 7 | J8: 8 | K8: 9 | L8: 10 | M8: 11 | N8: 12 | O8: 13 | P8: 14 | Q8: 15 | R8: 16 | S8: 17 | T8: 18 | U8: 19 | V8: 20 | W8: 21 | X8: 22 | Y8: 23 | Z8: 24 | AA8: 25 | AB8: 26 | AC8: 27 | AD8: 28 | AE8: 29 | AF8: V | AG8: 31
B9: FERNANDO LOURIDO | C9: 1 | D9: V | E9: V | F9: 4 | G9: 5 | H9: 6 | I9: 7 | J9: G | K9: G | L9: G | M9: G | N9: G | O9: G | P9: G | Q9: 15 | R9: 16 | S9: 17 | T9: 18 | U9: 19 | V9: 20 | W9: 21 | X9: 22 | Y9: 23 | Z9: 24 | AA9: 25 | AB9: 26 | AC9: 27 | AD9: 28 | AE9: 29 | AF9: 30 | AG9: 31
B10: FELIPE | C10: 1 | D10: 2 | E10: 3 | F10: 4 | G10: 5 | H10: 6 | I10: 7 | J10: 8 | K10: 9 | L10: 10 | M10: 11 | N10: 12 | O10: 13 | P10: 14 | Q10: 15 | R10: 16 | S10: 17 | T10: 18 | U10: 19 | V10: 20 | W10: 21 | X10: 22 | Y10: 23 | Z10: V | AA10: 25 | AB10: 26 | AC10: V | AD10: V | AE10: V | AF10: V | AG10: V
B11: 45323
C12: Sá | D12: Do | E12: Lu | F12: Ma | G12: Mi | H12: Ju | I12: Vi | J12: Sá | K12: Do | L12: Lu | M12: Ma | N12: Mi | O12: Ju | P12: Vi | Q12: Sá | R12: Do | S12: Lu | T12: Ma | U12: Mi | V12: Ju | W12: Vi | X12: Sá | Y12: Do | Z12: Lu | AA12: Ma | AB12: Mi | AC12: Ju | AD12: Vi | AI12: Fichero Oficial de Vacaciones 2025
B13: JORGE | C13: 1 | D13: 2 | E13: 3 | F13: 4 | G13: 5 | H13: 6 | I13: 7 | J13: 8 | K13: 9 | L13: 10 | M13: 11 | N13: 12 | O13: 13 | P13: 14 | Q13: 15 | R13: 16 | S13: 17 | T13: 18 | U13: 19 | V13: 20 | W13: 21 | X13: 22 | Y13: 23 | Z13: 24 | AA13: 25 | AB13: 26 | AC13: 27 | AD13: 28
B14: ISRAEL HURTADO | C14: 1 | D14: 2 | E14: 3 | F14: 4 | G14: 5 | H14: 6 | I14: 7 | J14: 8 | K14: 9 | L14: 10 | M14: 11 | N14: 12 | O14: 13 | P14: 14 | Q14: 15 | R14: 16 | S14: 17 | T14: 18 | U14: 19 | V14: 20 | W14: 21 | X14: 22 | Y14: 23 | Z14: 24 | AA14: 25 | AB14: 26 | AC14: 27 | AD14: 28
B15: CHEMA | C15: 1 | D15: 2 | E15: 3 | F15: 4 | G15: 5 | H15: 6 | I15: 7 | J15: 8 | K15: 9 | L15: 10 | M15: 11 | N15: 12 | O15: 13 | P15: 14 | Q15: 15 | R15: 16 | S15: 17 | T15: 18 | U15: 19 | V15: 20 | W15: 21 | X15: 22 | Y15: 23 | Z15: 24 | AA15: 25 | AB15: 26 | AC15: 27 | AD15: 28
B16: DANI | C16: 1 | D16: 2 | E16: 3 | F16: 4 | G16: 5 | H16: 6 | I16: 7 | J16: 8 | K16: 9 | L16: 10 | M16: 11 | N16: 12 | O16: 13 | P16: 14 | Q16: 15 | R16: 16 | S16: 17 | T16: 18 | U16: 19 | V16: 20 | W16: 21 | X16: 22 | Y16: 23 | Z16: 24 | AA16: 25 | AB16: 26 | AC16: 27 | AD16: 28
B17: EDUARDO | C17: 1 | D17: 2 | E17: 3 | F17: 4 | G17: 5 | H17: 6 | I17: 7 | J17: 8 | K17: 9 | L17: 10 | M17: 11 | N17: 12 | O17: 13 | P17: 14 | Q17: 15 | R17: 16 | S17: 17 | T17: 18 | U17: 19 | V17: 20 | W17: 21 | X17: 22 | Y17: 23 | Z17: 24 | AA17: 25 | AB17: 26 | AC17: 27 | AD17: 28
B18: FERNANDO LOURIDO | C18: 1 | D18: 2 | E18: 3 | F18: 4 | G18: 5 | H18: 6 | I18: 7 | J18: 8 | K18: 9 | L18: 10 | M18: 11 | N18: 12 | O18: 13 | P18: 14 | Q18: 15 | R18: 16 | S18: 17 | T18: 18 | U18: 19 | V18: 20 | W18: 21 | X18: 22 | Y18: 23 | Z18: 24 | AA18: 25 | AB18: 26 | AC18: 27 | AD18: 28
B20: 45352
C21: Sá | D21: Do | E21: Lu | F21: Ma | G21: Mi | H21: Ju | I21: Vi | J21: Sá | K21: Do | L21: Lu | M21: Ma | N21: Mi | O21: Ju | P21: Vi | Q21: Sá | R21: Do | S21: Lu | T21: Ma | U21: Mi | V21: Ju | W21: Vi | X21: Sá | Y21: Do | Z21: Lu | AA21: Ma | AB21: Mi | AC21: Ju | AD21: Vi | AE21: Sá | AF21: Do | AG21: Lu | AI21: Fichero Oficial de Vacaciones 2025
B22: JORGE | C22: 1 | D22: 2 | E22: 3 | F22: 4 | G22: 5 | H22: 6 | I22: 7 | J22: 8 | K22: 9 | L22: 10 | M22: 11 | N22: 12 | O22: 13 | P22: 14 | Q22: 15 | R22: 16 | S22: 17 | T22: 18 | U22: 19 | V22: 20 | W22: 21 | X22: 22 | Y22: 23 | Z22: 24 | AA22: 25 | AB22: 26 | AC22: 27 | AD22: 28 | AE22: 29 | AF22: 30 | AG22: 31
B23: ISRAEL HURTADO | C23: 1 | D23: 2 | E23: 3 | F23: 4 | G23: 5 | H23: 6 | I23: 7 | J23: 8 | K23: 9 | L23: 10 | M23: 11 | N23: 12 | O23: 13 | P23: 14 | Q23: 15 | R23: 16 | S23: 17 | T23: 18 | U23: 19 | V23: 20 | W23: 21 | X23: 22 | Y23: 23 | Z23: 24 | AA23: 25 | AB23: 26 | AC23: 27 | AD23: 28 | AE23: 29 | AF23: 30 | AG23: 31
B24: CHEMA | C24: 1 | D24: 2 | E24: 3 | F24: 4 | G24: 5 | H24: 6 | I24: 7 | J24: 8 | K24: 9 | L24: 10 | M24: 11 | N24: 12 | O24: 13 | P24: 14 | Q24: 15 | R24: 16 | S24: 17 | T24: 18 | U24: 19 | V24: 20 | W24: 21 | X24: 22 | Y24: 23 | Z24: 24 | AA24: 25 | AB24: 26 | AC24: 27 | AD24: 28 | AE24: 29 | AF24: 30 | AG24: 31
B25: DANI | C25: 1 | D25: 2 | E25: 3 | F25: 4 | G25: 5 | H25: 6 | I25: 7 | J25: 8 | K25: 9 | L25: 10 | M25: 11 | N25: 12 | O25: 13 | P25: 14 | Q25: 15 | R25: 16 | S25: 17 | T25: 18 | U25: 19 | V25: 20 | W25: 21 | X25: 22 | Y25: 23 | Z25: 24 | AA25: 25 | AB25: 26 | AC25: 27 | AD25: 28 | AE25: 29 | AF25: 30 | AG25: 31
B26: EDUARDO | C26: 1 | D26: 2 | E26: 3 | F26: 4 | G26: 5 | H26: 6 | I26: 7 | J26: 8 | K26: 9 | L26: 10 | M26: 11 | N26: 12 | O26: 13 | P26: 14 | Q26: 15 | R26: 16 | S26: 17 | T26: 18 | U26: 19 | V26: 20 | W26: 21 | X26: 22 | Y26: 23 | Z26: 24 | AA26: 25 | AB26: 26 | AC26: 27 | AD26: 28 | AE26: 29 | AF26: 30 | AG26: 31
B27: FERNANDO LOURIDO | C27: 1 | D27: 2 | E27: 3 | F27: 4 | G27: 5 | H27: 6 | I27: 7 | J27: 8 | K27: 9 | L27: 10 | M27: 11 | N27: 12 | O27: 13 | P27: 14 | Q27: 15 | R27: 16 | S27: 17 | T27: 18 | U27: 19 | V27: 20 | W27: 21 | X27: 22 | Y27: 23 | Z27: 24 | AA27: 25 | AB27: 26 | AC27: 27 | AD27: 28 | AE27: 29 | AF27: 30 | AG27: 31
B28: FELIPE | C28: 1 | D28: 2 | E28: 3 | F28: 4 | G28: 5 | H28: 6 | I28: 7 | J28: 8 | K28: 9 | L28: 10 | M28: 11 | N28: 12 | O28: 13 | P28: 14 | Q28: 15 | R28: 16 | S28: 17 | T28: 18 | U28: 19 | V28: 20 | W28: 21 | X28: 22 | Y28: 23 | Z28: 24 | AA28: 25 | AB28: 26 | AC28: 27 | AD28: 28 | AE28: 29 | AF28: 30 | AG28: 31
B29: 45383
C30: Ma | D30: Mi | E30: Ju | F30: Vi | G30: Sá | H30: Do | I30: Lu | J30: Ma | K30: Mi | L30: Ju | M30: Vi | N30: Sá | O30: Do | P30: Lu | Q30: Ma | R30: Mi | S30: Ju | T30: Vi | U30: Sá | V30: Do | W30: Lu | X30: Ma | Y30: Mi | Z30: Ju | AA30: Vi | AB30: Sá | AC30: Do | AD30: Lu | AE30: Ma | AF30: Mi | AI30: Fichero Oficial de Vacaciones 2025
B31: JORGE | C31: 1 | D31: 2 | E31: 3 | F31: 4 | G31: 5 | H31: 6 | I31: 7 | J31: 8 | K31: 9 | L31: 10 | M31: 11 | N31: 12 | O31: 13 | P31: 14 | Q31: 15 | R31: 16 | S31: 17 | T31: 18 | U31: 19 | V31: 20 | W31: 21 | X31: 22 | Y31: 23 | Z31: 24 | AA31: 25 | AB31: 26 | AC31: 27 | AD31: 28 | AE31: 29 | AF31: 30
B32: ISRAEL HURTADO | C32: 1 | D32: 2 | E32: 3 | F32: 4 | G32: 5 | H32: 6 | I32: 7 | J32: 8 | K32: 9 | L32: 10 | M32: 11 | N32: 12 | O32: 13 | P32: 14 | Q32: 15 | R32: 16 | S32: 17 | T32: 18 | U32: 19 | V32: 20 | W32: 21 | X32: 22 | Y32: 23 | Z32: 24 | AA32: 25 | AB32: 26 | AC32: 27 | AD32: 28 | AE32: 29 | AF32: 30
B33: CHEMA | C33: 1 | D33: 2 | E33: 3 | F33: 4 | G33: 5 | H33: 6 | I33: 7 | J33: 8 | K33: 9 | L33: 10 | M33: 11 | N33: 12 | O33: 13 | P33: 14 | Q33: 15 | R33: 16 | S33: 17 | T33: 18 | U33: 19 | V33: 20 | W33: 21 | X33: 22 | Y33: 23 | Z33: 24 | AA33: 25 | AB33: 26 | AC33: 27 | AD33: 28 | AE33: 29 | AF33: 30
B34: DANI | C34: 1 | D34: 2 | E34: 3 | F34: 4 | G34: 5 | H34: 6 | I34: 7 | J34: 8 | K34: 9 | L34: 10 | M34: 11 | N34: 12 | O34: 13 | P34: 14 | Q34: 15 | R34: 16 | S34: 17 | T34: 18 | U34: 19 | V34: 20 | W34: 21 | X34: 22 | Y34: 23 | Z34: 24 | AA34: 25 | AB34: 26 | AC34: 27 | AD34: 28 | AE34: 29 | AF34: 30
B35: EDUARDO | C35: 1 | D35: 2 | E35: 3 | F35: 4 | G35: 5 | H35: 6 | I35: 7 | J35: 8 | K35: 9 | L35: 10 | M35: 11 | N35: 12 | O35: 13 | P35: 14 | Q35: 15 | R35: 16 | S35: 17 | T35: 18 | U35: 19 | V35: 20 | W35: 21 | X35: 22 | Y35: 23 | Z35: 24 | AA35: 25 | AB35: 26 | AC35: 27 | AD35: 28 | AE35: 29 | AF35: 30
B36: FERNANDO LOURIDO | C36: 1 | D36: 2 | E36: 3 | F36: 4 | G36: 5 | H36: 6 | I36: 7 | J36: 8 | K36: 9 | L36: 10 | M36: 11 | N36: 12 | O36: 13 | P36: 14 | Q36: 15 | R36: 16 | S36: 17 | T36: 18 | U36: 19 | V36: 20 | W36: 21 | X36: 22 | Y36: 23 | Z36: 24 | AA36: 25 | AB36: 26 | AC36: 27 | AD36: 28 | AE36: 29 | AF36: 30
B37: FELIPE | C37: 1 | D37: 2 | E37: 3 | F37: 4 | G37: 5 | H37: 6 | I37: 7 | J37: 8 | K37: 9 | L37: 10 | M37: 11 | N37: 12 | O37: 13 | P37: 14 | Q37: 15 | R37: 16 | S37: 17 | T37: 18 | U37: 19 | V37: 20 | W37: 21 | X37: 22 | Y37: 23 | Z37: 24 | AA37: 25 | AB37: 26 | AC37: 27 | AD37: 28 | AE37: 29 | AF37: 30
B38: 45413
C39: Ju | D39: Vi | E39: Sá | F39: Do | G39: Lu | H39: Ma | I39: Mi | J39: Ju | K39: Vi | L39: Sá | M39: Do | N39: Lu | O39: Ma | P39: Mi | Q39: Ju | R39: Vi | S39: Sá | T39: Do | U39: Lu | V39: Ma | W39: Mi | X39: Ju | Y39: Vi | Z39: Sá | AA39: Do | AB39: Lu | AC39: Ma | AD39: Mi | AE39: Ju | AF39: Vi | AG39: Sá | AI39: Fichero Oficial de Vacaciones 2025
B40: JORGE | C40: 1 | D40: 2 | E40: 3 | F40: 4 | G40: 5 | H40: 6 | I40: 7 | J40: 8 | K40: 9 | L40: 10 | M40: 11 | N40: 12 | O40: 13 | P40: 14 | Q40: 15 | R40: 16 | S40: 17 | T40: 18 | U40: 19 | V40: 20 | W40: 21 | X40: 22 | Y40: 23 | Z40: 24 | AA40: 25 | AB40: 26 | AC40: 27 | AD40: 28 | AE40: 29 | AF40: 30 | AG40: 31
B41: ISRAEL HURTADO | C41: 1 | D41: 2 | E41: 3 | F41: 4 | G41: 5 | H41: 6 | I41: 7 | J41: 8 | K41: 9 | L41: 10 | M41: 11 | N41: 12 | O41: 13 | P41: 14 | Q41: 15 | R41: 16 | S41: 17 | T41: 18 | U41: 19 | V41: 20 | W41: 21 | X41: 22 | Y41: 23 | Z41: 24 | AA41: 25 | AB41: 26 | AC41: 27 | AD41: 28 | AE41: 29 | AF41: 30 | AG41: 31
B42: CHEMA | C42: 1 | D42: 2 | E42: 3 | F42: 4 | G42: 5 | H42: 6 | I42: 7 | J42: 8 | K42: 9 | L42: 10 | M42: 11 | N42: 12 | O42: 13 | P42: 14 | Q42: 15 | R42: 16 | S42: 17 | T42: 18 | U42: 19 | V42: 20 | W42: 21 | X42: 22 | Y42: 23 | Z42: 24 | AA42: 25 | AB42: 26 | AC42: 27 | AD42: 28 | AE42: 29 | AF42: 30 | AG42: 31
...

Sheet Guardias Networking 2026
A1: 46023
B2: Ju | C2: Vi | D2: Sá | E2: Do | F2: Lu | G2: Ma | H2: Mi | I2: Ju | J2: Vi | K2: Sá | L2: Do | M2: Lu | N2: Ma | O2: Mi | P2: Ju | Q2: Vi | R2: Sá | S2: Do | T2: Lu | U2: Ma | V2: Mi | W2: Ju | X2: Vi | Y2: Sá | Z2: Do | AA2: Lu | AB2: Ma | AC2: Mi | AD2: Ju | AE2: Vi | AF2: Sá | AH2: Cuadrante Spain Region v17 2026.xlsx
A3: JORGE | B3: 1 | C3: V | D3: 3 | E3: 4 | F3: V | G3: 6 | H3: V | I3: V | J3: V | K3: 10 | L3: 11 | M3: V | N3: V | O3: G | P3: G | Q3: G | R3: G | S3: G | T3: G | U3: G | V3: 21 | W3: 22 | X3: 23 | Y3: 24 | Z3: 25 | AA3: 26 | AB3: 27 | AC3: G | AD3: G | AE3: G | AF3: G
A4: ISRAEL HURTADO | B4: 1 | C4: V | D4: 3 | E4: 4 | F4: V | G4: 6 | H4: V | I4: V | J4: V | K4: 10 | L4: 11 | M4: V | N4: 13 | O4: 14 | P4: 15 | Q4: 16 | R4: 17 | S4: 18 | T4: 19 | U4: 20 | V4: G | W4: G | X4: G | Y4: G | Z4: G | AA4: G | AB4: G | AC4: 28 | AD4: 29 | AE4: 30 | AF4: 31
A5: CHEMA | B5: 1 | C5: 2 | D5: 3 | E5: 4 | F5: 5 | G5: 6 | H5: G | I5: G | J5: G | K5: G | L5: G | M5: G | N5: G | O5: 14 | P5: 15 | Q5: 16 | R5: 17 | S5: 18 | T5: 19 | U5: 20 | V5: 21 | W5: 22 | X5: 23 | Y5: 24 | Z5: 25 | AA5: 26 | AB5: 27 | AC5: 28 | AD5: V | AE5: V | AF5: 31
A6: DANI | B6: G | C6: G | D6: G | E6: G | F6: G | G6: G | H6: 7 | I6: 8 | J6: 9 | K6: 10 | L6: 11 | M6: 12 | N6: 13 | O6: 14 | P6: 15 | Q6: 16 | R6: 17 | S6: 18 | T6: 19 | U6: 20 | V6: 21 | W6: 22 | X6: 23 | Y6: 24 | Z6: 25 | AA6: 26 | AB6: 27 | AC6: 28 | AD6: 29 | AE6: 30 | AF6: 31
A7: EDUARDO | B7: 1 | C7: V | D7: 3 | E7: 4 | F7: V | G7: 6 | H7: V | I7: 8 | J7: 9 | K7: 10 | L7: 11 | M7: 12 | N7: 13 | O7: 14 | P7: 15 | Q7: V | R7: 17 | S7: 18 | T7: 19 | U7: 20 | V7: 21 | W7: 22 | X7: V | Y7: 24 | Z7: 25 | AA7: 26 | AB7: 27 | AC7: 28 | AD7: 29 | AE7: V | AF7: 31
A8: FERNANDO LOURIDO | B8: 1 | C8: 2 | D8: 3 | E8: 4 | F8: 5 | G8: 6 | H8: 7 | I8: 8 | J8: 9 | K8: 10 | L8: 11 | M8: 12 | N8: 13 | O8: 14 | P8: 15 | Q8: 16 | R8: 17 | S8: 18 | T8: V | U8: V | V8: V | W8: V | X8: Vi | Y8: 24 | Z8: 25 | AA8: 26 | AB8: 27 | AC8: 28 | AD8: 29 | AE8: 30 | AF8: 31
A9: MANUEL CABANA | B9: 1 | C9: 2 | D9: 3 | E9: 4 | F9: 5 | G9: 6 | H9: 7 | I9: 8 | J9: 9 | K9: 10 | L9: 11 | M9: 12 | N9: 13 | O9: 14 | P9: 15 | Q9: 16 | R9: 17 | S9: 18 | T9: 19 | U9: 20 | V9: 21 | W9: 22 | X9: 23 | Y9: 24 | Z9: 25 | AA9: 26 | AB9: 27 | AC9: 28 | AD9: 29 | AE9: 30 | AF9: 31
A10: 46054
B11: Do | C11: Lu | D11: Ma | E11: Mi | F11: Ju | G11: Vi | H11: Sá | I11: Do | J11: Lu | K11: Ma | L11: Mi | M11: Ju | N11: Vi | O11: Sá | P11: Do | Q11: Lu | R11: Ma | S11: Mi | T11: Ju | U11: Vi | V11: Sá | W11: Do | X11: Lu | Y11: Ma | Z11: Mi | AA11: Ju | AB11: Vi | AC11: Sá | AD11: Do | AE11: Lu
A12: JORGE | B12: G | C12: G | D12: G | E12: 4 | F12: 5 | G12: 6 | H12: 7 | I12: 8 | J12: 9 | K12: 10 | L12: 11 | M12: 12 | N12: 13 | O12: 14 | P12: 15 | Q12: A | R12: 17 | S12: 18 | T12: 19 | U12: 20 | V12: 21 | W12: 22 | X12: 23 | Y12: 24 | Z12: 25 | AA12: 26 | AB12: 27 | AC12: 28
A13: ISRAEL HURTADO | B13: 1 | C13: 2 | D13: 3 | E13: 4 | F13: 5 | G13: 6 | H13: 7 | I13: 8 | J13: 9 | K13: 10 | L13: G | M13: G | N13: G | O13: G | P13: G | Q13: G | R13: G | S13: 18 | T13: 19 | U13: 20 | V13: 21 | W13: 22 | X13: 23 | Y13: 24 | Z13: 25 | AA13: 26 | AB13: 27 | AC13: 28
A14: CHEMA | B14: 1 | C14: 2 | D14: 3 | E14: G | F14: G | G14: G | H14: G | I14: G | J14: G | K14: G | L14: 11 | M14: 12 | N14: 13 | O14: 14 | P14: 15 | Q14: 16 | R14: 17 | S14: 18 | T14: 19 | U14: 20 | V14: 21 | W14: 22 | X14: 23 | Y14: 24 | Z14: 25 | AA14: 26 | AB14: 27 | AC14: 28
A15: DANI | B15: 1 | C15: 2 | D15: 3 | E15: 4 | F15: 5 | G15: 6 | H15: 7 | I15: 8 | J15: 9 | K15: 10 | L15: 11 | M15: 12 | N15: 13 | O15: 14 | P15: 15 | Q15: 16 | R15: 17 | S15: 18 | T15: 19 | U15: 20 | V15: 21 | W15: 22 | X15: 23 | Y15: 24 | Z15: 25 | AA15: 26 | AB15: 27 | AC15: 28
A16: EDUARDO | B16: 1 | C16: 2 | D16: 3 | E16: 4 | F16: 5 | G16: 6 | H16: 7 | I16: 8 | J16: 9 | K16: 10 | L16: 11 | M16: 12 | N16: V | O16: 14 | P16: 15 | Q16: 16 | R16: A | S16: 18 | T16: A | U16: 20 | V16: 21 | W16: 22 | X16: 23 | Y16: 24 | Z16: 25 | AA16: 26 | AB16: 27 | AC16: 28
A17: FERNANDO LOURIDO | B17: 1 | C17: 2 | D17: 3 | E17: 4 | F17: 5 | G17: 6 | H17: 7 | I17: 8 | J17: 9 | K17: 10 | L17: 11 | M17: 12 | N17: 13 | O17: 14 | P17: 15 | Q17: 16 | R17: 17 | S17: G | T17: G | U17: G | V17: G | W17: G | X17: G | Y17: G | Z17: 25 | AA17: 26 | AB17: 27 | AC17: 28
A18: MANUEL CABANA | B18: 1 | C18: 2 | D18: 3 | E18: 4 | F18: 5 | G18: 6 | H18: 7 | I18: 8 | J18: 9 | K18: 10 | L18: 11 | M18: 12 | N18: 13 | O18: 14 | P18: 15 | Q18: 16 | R18: 17 | S18: 18 | T18: 19 | U18: 20 | V18: 21 | W18: 22 | X18: 23 | Y18: 24 | Z18: G | AA18: G | AB18: G | AC18: G
A19: 46082
B20: Do | C20: Lu | D20: Ma | E20: Mi | F20: Ju | G20: Vi | H20: Sá | I20: Do | J20: Lu | K20: Ma | L20: Mi | M20: Ju | N20: Vi | O20: Sá | P20: Do | Q20: Lu | R20: Ma | S20: Mi | T20: Ju | U20: Vi | V20: Sá | W20: Do | X20: Lu | Y20: Ma | Z20: Mi | AA20: Ju | AB20: Vi | AC20: Sá | AD20: Do | AE20: Lu | AF20: Ma
A21: JORGE | B21: 1 | C21: 2 | D21: 3 | E21: 4 | F21: 5 | G21: 6 | H21: 7 | I21: 8 | J21: 9 | K21: 10 | L21: 11 | M21: 12 | N21: 13 | O21: 14 | P21: 15 | Q21: 16 | R21: 17 | S21: 18 | T21: 19 | U21: 20 | V21: 21 | W21: 22 | X21: 23 | Y21: 24 | Z21: G | AA21: G | AB21: G | AC21: G | AD21: G | AE21: G | AF21: G
A22: ISRAEL HURTADO | B22: 1 | C22: 2 | D22: 3 | E22: 4 | F22: 5 | G22: 6 | H22: 7 | I22: 8 | J22: 9 | K22: 10 | L22: A | M22: 12 | N22: 13 | O22: 14 | P22: 15 | Q22: A | R22: 17 | S22: G | T22: G | U22: G | V22: G | W22: G | X22: G | Y22: G | Z22: 25 | AA22: 26 | AB22: 27 | AC22: 28 | AD22: 29 | AE22: 30 | AF22: 31
A23: CHEMA | B23: 1 | C23: 2 | D23: 3 | E23: 4 | F23: 5 | G23: 6 | H23: 7 | I23: 8 | J23: 9 | K23: 10 | L23: G | M23: G | N23: G | O23: G | P23: G | Q23: G | R23: G | S23: 18 | T23: 19 | U23: 20 | V23: 21 | W23: 22 | X23: 23 | Y23: 24 | Z23: 25 | AA23: 26 | AB23: 27 | AC23: 28 | AD23: 29 | AE23: 30 | AF23: 31
A24: DANI | B24: 1 | C24: 2 | D24: 3 | E24: G | F24: G | G24: G | H24: G | I24: G | J24: G | K24: G | L24: 11 | M24: 12 | N24: A | O24: 14 | P24: 15 | Q24: 16 | R24: 17 | S24: 18 | T24: 19 | U24: 20 | V24: 21 | W24: 22 | X24: 23 | Y24: 24 | Z24: 25 | AA24: 26 | AB24: 27 | AC24: 28 | AD24: 29 | AE24: V | AF24: V
A25: EDUARDO | B25: 1 | C25: 2 | D25: 3 | E25: 4 | F25: 5 | G25: 6 | H25: 7 | I25: 8 | J25: 9 | K25: 10 | L25: 11 | M25: 12 | N25: 13 | O25: 14 | P25: 15 | Q25: 16 | R25: 17 | S25: 18 | T25: 19 | U25: 20 | V25: 21 | W25: 22 | X25: 23 | Y25: 24 | Z25: 25 | AA25: 26 | AB25: 27 | AC25: 28 | AD25: 29 | AE25: V | AF25: V
A26: FERNANDO LOURIDO | B26: 1 | C26: 2 | D26: 3 | E26: 4 | F26: 5 | G26: 6 | H26: 7 | I26: 8 | J26: 9 | K26: 10 | L26: 11 | M26: 12 | N26: 13 | O26: 14 | P26: 15 | Q26: 16 | R26: 17 | S26: 18 | T26: 19 | U26: 20 | V26: 21 | W26: 22 | X26: 23 | Y26: 24 | Z26: 25 | AA26: 26 | AB26: 27 | AC26: 28 | AD26: 29 | AE26: 30 | AF26: 31
A27: MANUEL CABANA | B27: G | C27: G | D27: G | E27: 4 | F27: 5 | G27: 6 | H27: 7 | I27: 8 | J27: 9 | K27: 10 | L27: 11 | M27: 12 | N27: 13 | O27: 14 | P27: 15 | Q27: 16 | R27: 17 | S27: 18 | T27: 19 | U27: 20 | V27: 21 | W27: 22 | X27: 23 | Y27: 24 | Z27: 25 | AA27: 26 | AB27: 27 | AC27: 28 | AD27: 29 | AE27: 30 | AF27: 31
A28: 46113
B29: Mi | C29: Ju | D29: Vi | E29: Sá | F29: Do | G29: Lu | H29: Ma | I29: Mi | J29: Ju | K29: Vi | L29: Sá | M29: Do | N29: Lu | O29: Ma | P29: Mi | Q29: Ju | R29: Vi | S29: Sá | T29: Do | U29: Lu | V29: Ma | W29: Mi | X29: Ju | Y29: Vi | Z29: Sá | AA29: Do | AB29: Lu | AC29: Ma | AD29: Mi | AE29: Ju
A30: JORGE | B30: G | C30: G | D30: G | E30: G | F30: G | G30: G | H30: G | I30: 8 | J30: 9 | K30: 10 | L30: 11 | M30: 12 | N30: 13 | O30: 14 | P30: 15 | Q30: 16 | R30: 17 | S30: 18 | T30: 19 | U30: 20 | V30: 21 | W30: 22 | X30: 23 | Y30: 24 | Z30: 25 | AA30: 26 | AB30: 27 | AC30: 28 | AD30: 29 | AE30: 30
A31: ISRAEL HURTADO | B31: 1 | C31: 2 | D31: 3 | E31: 4 | F31: 5 | G31: A | H31: A | I31: 8 | J31: 9 | K31: 10 | L31: 11 | M31: 12 | N31: A | O31: 14 | P31: G | Q31: G | R31: G | S31: G | T31: G | U31: G | V31: G | W31: 22 | X31: 23 | Y31: 24 | Z31: 25 | AA31: 26 | AB31: 27 | AC31: 28 | AD31: G | AE31: G
A32: CHEMA | B32: 1 | C32: 2 | D32: 3 | E32: 4 | F32: 5 | G32: A | H32: A | I32: G | J32: G | K32: G | L32: G | M32: G | N32: G | O32: G | P32: 15 | Q32: 16 | R32: 17 | S32: 18 | T32: 19 | U32: 20 | V32: 21 | W32: 22 | X32: 23 | Y32: 24 | Z32: 25 | AA32: 26 | AB32: 27 | AC32: 28 | AD32: 29 | AE32: A
A33: DANI | B33: V | C33: 2 | D33: 3 | E33: 4 | F33: 5 | G33: 6 | H33: 7 | I33: 8 | J33: 9 | K33: 10 | L33: 11 | M33: 12 | N33: 13 | O33: 14 | P33: 15 | Q33: 16 | R33: 17 | S33: 18 | T33: 19 | U33: 20 | V33: 21 | W33: 22 | X33: 23 | Y33: 24 | Z33: 25 | AA33: 26 | AB33: 27 | AC33: 28 | AD33: 29 | AE33: 30
A34: EDUARDO | B34: V | C34: 2 | D34: 3 | E34: 4 | F34: 5 | G34: 6 | H34: 7 | I34: 8 | J34: 9 | K34: 10 | L34: 11 | M34: 12 | N34: 13 | O34: 14 | P34: 15 | Q34: 16 | R34: 17 | S34: 18 | T34: 19 | U34: 20 | V34: 21 | W34: 22 | X34: 23 | Y34: 24 | Z34: 25 | AA34: 26 | AB34: 27 | AC34: 28 | AD34: 29 | AE34: 30
A35: FERNANDO LOURIDO | B35: 1 | C35: 2 | D35: 3 | E35: 4 | F35: 5 | G35: 6 | H35: 7 | I35: 8 | J35: 9 | K35: 10 | L35: 11 | M35: 12 | N35: 13 | O35: 14 | P35: 15 | Q35: 16 | R35: 17 | S35: 18 | T35: 19 | U35: 20 | V35: 21 | W35: G | X35: G | Y35: G | Z35: G | AA35: G | AB35: G | AC35: G | AD35: 29 | AE35: 30
A36: MANUEL CABANA | B36: 1 | C36: 2 | D36: 3 | E36: 4 | F36: 5 | G36: 6 | H36: 7 | I36: 8 | J36: A | K36: A | L36: 11 | M36: 12 | N36: 13 | O36: 14 | P36: 15 | Q36: A | R36: 17 | S36: 18 | T36: 19 | U36: 20 | V36: 21 | W36: 22 | X36: 23 | Y36: 24 | Z36: 25 | AA36: 26 | AB36: V | AC36: V | AD36: V | AE36: V
A37: 46143
B38: Vi | C38: Sá | D38: Do | E38: Lu | F38: Ma | G38: Mi | H38: Ju | I38: Vi | J38: Sá | K38: Do | L38: Lu | M38: Ma | N38: Mi | O38: Ju | P38: Vi | Q38: Sá | R38: Do | S38: Lu | T38: Ma | U38: Mi | V38: Ju | W38: Vi | X38: Sá | Y38: Do | Z38: Lu | AA38: Ma | AB38: Mi | AC38: Ju | AD38: Vi | AE38: Sá | AF38: Do
A39: JORGE | B39: 1 | C39: 2 | D39: 3 | E39: 4 | F39: 5 | G39: 6 | H39: 7 | I39: 8 | J39: 9 | K39: 10 | L39: 11 | M39: 12 | N39: 13 | O39: 14 | P39: 15 | Q39: 16 | R39: 17 | S39: 18 | T39: 19 | U39: G | V39: G | W39: G | X39: G | Y39: G | Z39: G | AA39: G | AB39: 27 | AC39: 28 | AD39: 29 | AE39: 30 | AF39: 31
A40: ISRAEL HURTADO | B40: G | C40: G | D40: G | E40: G | F40: G | G40: 6 | H40: 7 | I40: 8 | J40: 9 | K40: 10 | L40: 11 | M40: 12 | N40: 13 | O40: 14 | P40: 15 | Q40: 16 | R40: 17 | S40: 18 | T40: 19 | U40: 20 | V40: 21 | W40: 22 | X40: 23 | Y40: 24 | Z40: 25 | AA40: 26 | AB40: 27 | AC40: 28 | AD40: 29 | AE40: 30 | AF40: 31
...

Sheet Guardias Networking 2025
A1: 45658 | AH1: Fichero Vacaciones Oficial 2025 - OLD
B2: Mi | C2: Ju | D2: Vi | E2: Sá | F2: Do | G2: Lu | H2: Ma | I2: Mi | J2: Ju | K2: Vi | L2: Sá | M2: Do | N2: Lu | O2: Ma | P2: Mi | Q2: Ju | R2: Vi | S2: Sá | T2: Do | U2: Lu | V2: Ma | W2: Mi | X2: Ju | Y2: Vi | Z2: Sá | AA2: Do | AB2: Lu | AC2: Ma | AD2: Mi | AE2: Ju | AF2: Vi
A3: JORGE | B3: 1 | C3: 2 | D3: 3 | E3: 4 | F3: 5 | G3: 6 | H3: 7 | I3: 8 | J3: 9 | K3: 10 | L3: 11 | M3: 12 | N3: 13 | O3: 14 | P3: 15 | Q3: 16 | R3: 17 | S3: 18 | T3: 19 | U3: 20 | V3: 21 | W3: 22 | X3: V | Y3: V | Z3: 25 | AA3: 26 | AB3: V | AC3: V | AD3: V | AE3: V | AF3: V | AH3: Fichero de vacaciones oficial 2025 - NEW
A4: ISRAEL HURTADO | B4: 1 | C4: V | D4: V | E4: 4 | F4: 5 | G4: 6 | H4: V | I4: V | J4: V | K4: V | L4: 11 | M4: 12 | N4: 13 | O4: 14 | P4: G | Q4: G | R4: G | S4: G | T4: G | U4: G | V4: G | W4: 22 | X4: V | Y4: 24 | Z4: 25 | AA4: 26 | AB4: 27 | AC4: 28 | AD4: 29 | AE4: 30 | AF4: 31
A5: CHEMA | B5: 1 | C5: 2 | D5: 3 | E5: 4 | F5: 5 | G5: 6 | H5: 7 | I5: 8 | J5: 9 | K5: 10 | L5: 11 | M5: 12 | N5: 13 | O5: 14 | P5: 15 | Q5: 16 | R5: 17 | S5: 18 | T5: 19 | U5: 20 | V5: 21 | W5: G | X5: G | Y5: G | Z5: G | AA5: G | AB5: G | AC5: G | AD5: 29 | AE5: 30 | AF5: 31
A6: DANI | B6: G | C6: G | D6: G | E6: G | F6: G | G6: G | H6: G | I6: 8 | J6: 9 | K6: 10 | L6: 11 | M6: 12 | N6: 13 | O6: 14 | P6: 15 | Q6: 16 | R6: 17 | S6: 18 | T6: 19 | U6: 20 | V6: 21 | W6: 22 | X6: 23 | Y6: 24 | Z6: 25 | AA6: 26 | AB6: 27 | AC6: 28 | AD6: 29 | AE6: 30 | AF6: 31
A7: EDUARDO | B7: 1 | C7: V | D7: V | E7: 4 | F7: 5 | G7: 6 | H7: 7 | I7: 8 | J7: 9 | K7: 10 | L7: 11 | M7: 12 | N7: 13 | O7: 14 | P7: 15 | Q7: 16 | R7: 17 | S7: 18 | T7: 19 | U7: 20 | V7: 21 | W7: 22 | X7: 23 | Y7: 24 | Z7: 25 | AA7: 26 | AB7: 27 | AC7: 28 | AD7: 29 | AE7: 30 | AF7: 31
A8: FERNANDO LOURIDO | B8: 1 | C8: V | D8: V | E8: 4 | F8: 5 | G8: 6 | H8: 7 | I8: G | J8: G | K8: G | L8: G | M8: G | N8: G | O8: G | P8: 15 | Q8: 16 | R8: 17 | S8: 18 | T8: 19 | U8: 20 | V8: 21 | W8: 22 | X8: 23 | Y8: 24 | Z8: 25 | AA8: 26 | AB8: 27 | AC8: 28 | AD8: G | AE8: G | AF8: G
A9: 45689
B10: Sá | C10: Do | D10: Lu | E10: Ma | F10: Mi | G10: Ju | H10: Vi | I10: Sá | J10: Do | K10: Lu | L10: Ma | M10: Mi | N10: Ju | O10: Vi | P10: Sá | Q10: Do | R10: Lu | S10: Ma | T10: Mi | U10: Ju | V10: Vi | W10: Sá | X10: Do | Y10: Lu | Z10: Ma | AA10: Mi | AB10: Ju | AC10: Vi
A11: JORGE | B11: 1 | C11: 2 | D11: V | E11: 4 | F11: G | G11: G | H11: G | I11: G | J11: G | K11: G | L11: G | M11: 12 | N11: 13 | O11: 14 | P11: 15 | Q11: 16 | R11: 17 | S11: 18 | T11: 19 | U11: 20 | V11: 21 | W11: 22 | X11: 23 | Y11: 24 | Z11: 25 | AA11: G | AB11: G | AC11: G
A12: ISRAEL HURTADO | B12: 1 | C12: 2 | D12: 3 | E12: 4 | F12: 5 | G12: 6 | H12: 7 | I12: 8 | J12: 9 | K12: 10 | L12: 11 | M12: 12 | N12: 13 | O12: 14 | P12: 15 | Q12: 16 | R12: 17 | S12: 18 | T12: G | U12: G | V12: G | W12: G | X12: G | Y12: G | Z12: G | AA12: 26 | AB12: 27 | AC12: 28
A13: CHEMA | B13: 1 | C13: 2 | D13: 3 | E13: 4 | F13: 5 | G13: 6 | H13: 7 | I13: 8 | J13: 9 | K13: 10 | L13: 11 | M13: G | N13: G | O13: G | P13: G | Q13: G | R13: G | S13: G | T13: 19 | U13: 20 | V13: 21 | W13: 22 | X13: 23 | Y13: 24 | Z13: 25 | AA13: 26 | AB13: 27 | AC13: 28
A14: DANI | B14: 1 | C14: 2 | D14: 3 | E14: 4 | F14: 5 | G14: 6 | H14: 7 | I14: 8 | J14: 9 | K14: 10 | L14: 11 | M14: 12 | N14: 13 | O14: 14 | P14: 15 | Q14: 16 | R14: 17 | S14: 18 | T14: 19 | U14: 20 | V14: 21 | W14: 22 | X14: 23 | Y14: 24 | Z14: 25 | AA14: 26 | AB14: 27 | AC14: C
A15: EDUARDO | B15: 1 | C15: 2 | D15: 3 | E15: 4 | F15: 5 | G15: 6 | H15: 7 | I15: 8 | J15: 9 | K15: 10 | L15: 11 | M15: 12 | N15: 13 | O15: 14 | P15: 15 | Q15: 16 | R15: 17 | S15: 18 | T15: 19 | U15: 20 | V15: 21 | W15: 22 | X15: 23 | Y15: 24 | Z15: 25 | AA15: 26 | AB15: 27 | AC15: 28
A16: FERNANDO LOURIDO | B16: G | C16: G | D16: G | E16: G | F16: 5 | G16: 6 | H16: 7 | I16: 8 | J16: 9 | K16: 10 | L16: 11 | M16: 12 | N16: 13 | O16: 14 | P16: 15 | Q16: 16 | R16: 17 | S16: 18 | T16: 19 | U16: 20 | V16: 21 | W16: 22 | X16: 23 | Y16: 24 | Z16: 25 | AA16: 26 | AB16: 27 | AC16: 28
A17: 45717
B18: Sá | C18: Do | D18: Lu | E18: Ma | F18: Mi | G18: Ju | H18: Vi | I18: Sá | J18: Do | K18: Lu | L18: Ma | M18: Mi | N18: Ju | O18: Vi | P18: Sá | Q18: Do | R18: Lu | S18: Ma | T18: Mi | U18: Ju | V18: Vi | W18: Sá | X18: Do | Y18: Lu | Z18: Ma | AA18: Mi | AB18: Ju | AC18: Vi | AD18: Sá | AE18: Do | AF18: Lu
A19: JORGE | B19: G | C19: G | D19: G | E19: G | F19: 5 | G19: 6 | H19: 7 | I19: 8 | J19: 9 | K19: 10 | L19: 11 | M19: 12 | N19: 13 | O19: 14 | P19: 15 | Q19: 16 | R19: 17 | S19: 18 | T19: 19 | U19: 20 | V19: 21 | W19: 22 | X19: 23 | Y19: 24 | Z19: 25 | AA19: 26 | AB19: 27 | AC19: 28 | AD19: 29 | AE19: 30 | AF19: 31
A20: ISRAEL HURTADO | B20: 1 | C20: 2 | D20: 3 | E20: 4 | F20: 5 | G20: 6 | H20: 7 | I20: 8 | J20: 9 | K20: 10 | L20: 11 | M20: 12 | N20: 13 | O20: 14 | P20: 15 | Q20: 16 | R20: 17 | S20: 18 | T20: 19 | U20: 20 | V20: 21 | W20: 22 | X20: 23 | Y20: 24 | Z20: 25 | AA20: G | AB20: G | AC20: G | AD20: G | AE20: G | AF20: G
A21: CHEMA | B21: 1 | C21: 2 | D21: 3 | E21: 4 | F21: 5 | G21: 6 | H21: 7 | I21: 8 | J21: 9 | K21: 10 | L21: 11 | M21: 12 | N21: 13 | O21: 14 | P21: 15 | Q21: 16 | R21: 17 | S21: 18 | T21: G | U21: G | V21: G | W21: G | X21: G | Y21: G | Z21: G | AA21: 26 | AB21: 27 | AC21: 28 | AD21: 29 | AE21: 30 | AF21: 31
A22: DANI | B22: 1 | C22: 2 | D22: C | E22: 4 | F22: G | G22: G | H22: G | I22: G | J22: G | K22: G | L22: G | M22: 12 | N22: 13 | O22: 14 | P22: 15 | Q22: 16 | R22: 17 | S22: 18 | T22: 19 | U22: 20 | V22: 21 | W22: 22 | X22: 23 | Y22: 24 | Z22: 25 | AA22: 26 | AB22: 27 | AC22: 28 | AD22: 29 | AE22: 30 | AF22: 31
A23: EDUARDO | B23: 1 | C23: 2 | D23: 3 | E23: 4 | F23: 5 | G23: 6 | H23: 7 | I23: 8 | J23: 9 | K23: 10 | L23: 11 | M23: G | N23: G | O23: G | P23: G | Q23: G | R23: G | S23: G | T23: 19 | U23: 20 | V23: 21 | W23: 22 | X23: 23 | Y23: 24 | Z23: 25 | AA23: 26 | AB23: 27 | AC23: 28 | AD23: 29 | AE23: 30 | AF23: 31
A24: FERNANDO LOURIDO | B24: 1 | C24: 2 | D24: 3 | E24: 4 | F24: 5 | G24: 6 | H24: 7 | I24: 8 | J24: 9 | K24: 10 | L24: 11 | M24: 12 | N24: 13 | O24: 14 | P24: 15 | Q24: 16 | R24: 17 | S24: 18 | T24: 19 | U24: 20 | V24: 21 | W24: 22 | X24: 23 | Y24: 24 | Z24: 25 | AA24: 26 | AB24: 27 | AC24: 28 | AD24: 29 | AE24: 30 | AF24: 31
A25: 45748
B26: Ma | C26: Mi | D26: Ju | E26: Vi | F26: Sá | G26: Do | H26: Lu | I26: Ma | J26: Mi | K26: Ju | L26: Vi | M26: Sá | N26: Do | O26: Lu | P26: Ma | Q26: Mi | R26: Ju | S26: Vi | T26: Sá | U26: Do | V26: Lu | W26: Ma | X26: Mi | Y26: Ju | Z26: Vi | AA26: Sá | AB26: Do | AC26: Lu | AD26: Ma | AE26: Mi
A27: JORGE | B27: 1 | C27: G | D27: G | E27: G | F27: G | G27: G | H27: G | I27: G | J27: 9 | K27: 10 | L27: 11 | M27: 12 | N27: 13 | O27: 14 | P27: 15 | Q27: 16 | R27: 17 | S27: 18 | T27: 19 | U27: 20 | V27: 21 | W27: 22 | X27: 23 | Y27: 24 | Z27: 25 | AA27: 26 | AB27: 27 | AC27: 28 | AD27: 29 | AE27: 30
A28: ISRAEL HURTADO | B28: G | C28: 2 | D28: 3 | E28: 4 | F28: 5 | G28: 6 | H28: 7 | I28: 8 | J28: 9 | K28: 10 | L28: 11 | M28: 12 | N28: 13 | O28: 14 | P28: 15 | Q28: G | R28: G | S28: G | T28: G | U28: G | V28: G | W28: G | X28: 23 | Y28: 24 | Z28: 25 | AA28: 26 | AB28: 27 | AC28: 28 | AD28: 29 | AE28: 30
A29: CHEMA | B29: 1 | C29: 2 | D29: 3 | E29: 4 | F29: 5 | G29: 6 | H29: 7 | I29: 8 | J29: 9 | K29: 10 | L29: 11 | M29: 12 | N29: 13 | O29: V | P29: V | Q29: V | R29: 17 | S29: 18 | T29: 19 | U29: 20 | V29: 21 | W29: 22 | X29: G | Y29: G | Z29: G | AA29: G | AB29: G | AC29: G | AD29: G | AE29: 30
A30: DANI | B30: 1 | C30: 2 | D30: 3 | E30: 4 | F30: 5 | G30: 6 | H30: 7 | I30: 8 | J30: 9 | K30: 10 | L30: 11 | M30: 12 | N30: 13 | O30: V | P30: V | Q30: V | R30: 17 | S30: 18 | T30: 19 | U30: 20 | V30: 21 | W30: 22 | X30: 23 | Y30: 24 | Z30: 25 | AA30: 26 | AB30: 27 | AC30: 28 | AD30: 29 | AE30: 30
A31: EDUARDO | B31: 1 | C31: 2 | D31: 3 | E31: 4 | F31: 5 | G31: 6 | H31: 7 | I31: 8 | J31: G | K31: G | L31: G | M31: G | N31: G | O31: G | P31: G | Q31: 16 | R31: 17 | S31: 18 | T31: 19 | U31: 20 | V31: 21 | W31: 22 | X31: 23 | Y31: 24 | Z31: 25 | AA31: 26 | AB31: 27 | AC31: 28 | AD31: 29 | AE31: 30
A32: FERNANDO LOURIDO | B32: 1 | C32: 2 | D32: 3 | E32: 4 | F32: 5 | G32: 6 | H32: 7 | I32: 8 | J32: 9 | K32: 10 | L32: 11 | M32: 12 | N32: 13 | O32: 14 | P32: 15 | Q32: 16 | R32: 17 | S32: 18 | T32: 19 | U32: 20 | V32: V | W32: V | X32: V | Y32: V | Z32: 25 | AA32: 26 | AB32: 27 | AC32: 28 | AD32: 29 | AE32: G
A33: 45778
B34: Ju | C34: Vi | D34: Sá | E34: Do | F34: Lu | G34: Ma | H34: Mi | I34: Ju | J34: Vi | K34: Sá | L34: Do | M34: Lu | N34: Ma | O34: Mi | P34: Ju | Q34: Vi | R34: Sá | S34: Do | T34: Lu | U34: Ma | V34: Mi | W34: Ju | X34: Vi | Y34: Sá | Z34: Do | AA34: Lu | AB34: Ma | AC34: Mi | AD34: Ju | AE34: Vi | AF34: Sá
A35: JORGE | B35: 1 | C35: 2 | D35: 3 | E35: 4 | F35: 5 | G35: 6 | H35: 7 | I35: 8 | J35: 9 | K35: 10 | L35: 11 | M35: 12 | N35: 13 | O35: 14 | P35: 15 | Q35: 16 | R35: 17 | S35: 18 | T35: 19 | U35: 20 | V35: G | W35: G | X35: G | Y35: G | Z35: G | AA35: G | AB35: G | AC35: G | AD35: G | AE35: G | AF35: G
A36: ISRAEL HURTADO | B36: 1 | C36: 2 | D36: 3 | E36: 4 | F36: 5 | G36: 6 | H36: G | I36: G | J36: G | K36: G | L36: G | M36: G | N36: G | O36: 14 | P36: 15 | Q36: V | R36: 17 | S36: 18 | T36: 19 | U36: 20 | V36: 21 | W36: 22 | X36: 23 | Y36: 24 | Z36: 25 | AA36: 26 | AB36: 27 | AC36: 28 | AD36: 29 | AE36: 30 | AF36: 31
A37: CHEMA | B37: 1 | C37: 2 | D37: 3 | E37: 4 | F37: 5 | G37: 6 | H37: 7 | I37: 8 | J37: 9 | K37: 10 | L37: 11 | M37: 12 | N37: 13 | O37: G | P37: G | Q37: G | R37: G | S37: G | T37: G | U37: G | V37: 21 | W37: 22 | X37: 23 | Y37: 24 | Z37: 25 | AA37: 26 | AB37: 27 | AC37: 28 | AD37: 29 | AE37: 30 | AF37: 31
A38: DANI | B38: 1 | C38: 2 | D38: 3 | E38: 4 | F38: 5 | G38: 6 | H38: 7 | I38: 8 | J38: 9 | K38: 10 | L38: 11 | M38: 12 | N38: 13 | O38: 14 | P38: 15 | Q38: 16 | R38: 17 | S38: 18 | T38: 19 | U38: 20 | V38: 21 | W38: 22 | X38: 23 | Y38: 24 | Z38: 25 | AA38: 26 | AB38: 27 | AC38: 28 | AD38: 29 | AE38: 30 | AF38: 31
A39: EDUARDO | B39: 1 | C39: 2 | D39: 3 | E39: 4 | F39: V | G39: 6 | H39: 7 | I39: 8 | J39: 9 | K39: 10 | L39: 11 | M39: 12 | N39: 13 | O39: 14 | P39: 15 | Q39: 16 | R39: 17 | S39: 18 | T39: 19 | U39: 20 | V39: 21 | W39: 22 | X39: 23 | Y39: 24 | Z39: 25 | AA39: 26 | AB39: 27 | AC39: 28 | AD39: 29 | AE39: 30 | AF39: 31
A40: FERNANDO LOURIDO | B40: G | C40: G | D40: G | E40: G | F40: G | G40: G | H40: 7 | I40: 8 | J40: 9 | K40: 10 | L40: 11 | M40: 12 | N40: 13 | O40: 14 | P40: 15 | Q40: 16 | R40: 17 | S40: 18 | T40: 19 | U40: 20 | V40: 21 | W40: 22 | X40: 23 | Y40: 24 | Z40: 25 | AA40: 26 | AB40: 27 | AC40: 28 | AD40: 29 | AE40: 30 | AF40: 31
...

Sheet TT NAVIDADES 2025-2026
D1: S | E1: D | F1: L | G1: M | H1: MI | I1: JU | J1: VI | K1: S | L1: D | M1: L | N1: M | O1: MI
B2: Nombre | C2: Mes | D2: 20 | E2: 21 | F2: 22 | G2: 23 | H2: 24 | I2: 25 | J2: 26 | K2: 27 | L2: 28 | M2: 29 | N2: 30 | O2: 31
B3: Israel Hurtado Arribas | C3: Diciembre | D3: F | E3: F | F3: 1 | G3: 1 | H3: 0 | I3: F | J3: 0 | K3: F | L3: F | M3: 1 | N3: 0 | O3: V
B4: Daniel Portugues Moncalvillo | C4: Diciembre | D4: F | E4: F | F4: V | G4: V | H4: A | I4: F | J4: V | K4: F | L4: F | M4: V | N4: V | O4: 0
B5: Jose María Andres Becerra | C5: Diciembre | D5: F | E5: F | F5: V | G5: V | H5: V | I5: F | J5: A | K5: F | L5: F | M5: 1 | N5: 0 | O5: A
B6: Fernando Miguel Lourido | C6: Diciembre | D6: F | E6: F | F6: 0 | G6: 0 | H6: 1 | I6: F | J6: 1 | K6: F | L6: F | M6: 0 | N6: 1 | O6: 1
B7: Jorge Zamorano | C7: Diciembre | D7: F | E7: F | F7: 0 | G7: 1 | H7: 0 | I7: F | J7: 1 | K7: F | L7: F | M7: 0 | N7: 1 | O7: A
B8: Katherine Llantoy | C8: Diciembre | D8: F | E8: F | F8: V | G8: V | H8: V | I8: F | J8: A | K8: F | L8: F | M8: V | N8: V | O8: 1
B9: Eduardo Rodriguez Izquierdo | C9: Diciembre | D9: F | E9: F | F9: 0 | G9: 1 | H9: 1 | I9: F | J9: 0 | K9: F | L9: F | M9: V | N9: V | O9: A
B10: Manuel Alejandro Cabana | C10: Diciembre | D10: F | E10: F | F10: 1 | G10: V | H10: V | I10: F | J10: V | K10: F | L10: F | M10: V | N10: V | O10: A
B11: Roberto Padovano Gonzalez | C11: Diciembre | D11: F | E11: F | F11: A | G11: A | H11: V | I11: F | J11: V | K11: F | L11: F | M11: V | N11: V | O11: V
B12: TOTAL | F12: =SUM(F3:F11) -> 2 | G12: =SUM(G3:G11) -> 3 | H12: =SUM(H3:H11) -> 2 | J12: =SUM(J3:J11) -> 2 | M12: =SUM(M3:M11) -> 2 | N12: =SUM(N3:N11) -> 2 | O12: =SUM(O3:O11) -> 2
D14: J | E14: V | F14: S | G14: D | H14: L | I14: M | J14: MI | K14: J | L14: V | M14: S | N14: D
B15: Nombre | C15: Mes | D15: 1 | E15: 2 | F15: 3 Ro | G15: 4 | H15: 5 Fr | I15: 6 | J15: 7 | K15: 8 | L15: 9 | M15: 10 | N15: 11
B16: Daniel Portugues Moncalvillo | C16: Enero | D16: F | E16: 0 | F16: F | G16: F | H16: 1 | I16: F | J16: 0 | K16: 0 | L16: 1 | M16: F | N16: F
B17: Eduardo Rodriguez Izquierdo | C17: Enero | D17: F | E17: V | F17: F | G17: F | H17: V | I17: F | J17: V | K17: 0 | L17: 1 | M17: F | N17: F
B18: Fernando Miguel Lourido | C18: Enero | D18: F | E18: 1 | F18: F | G18: F | H18: 0 | I18: F | J18: 1 | K18: 1 | L18: 0 | M18: F | N18: F
B19: Israel Hurtado Arribas | C19: Enero | D19: F | E19: V | F19: F | G19: F | H19: V | I19: F | J19: V | K19: V | L19: V | M19: F | N19: F
B20: Jorge Zamorano | C20: Enero | D20: F | E20: V | F20: F | G20: F | H20: V | I20: F | J20: V | K20: V | L20: V | M20: F | N20: F
B21: Roberto Padovano Gonzalez | C21: Enero | D21: F | E21: V | F21: F | G21: F | H21: A | I21: F | J21: V | K21: v | L21: 1 | M21: F | N21: F
B22: Jose María Andres Becerra | C22: Enero | D22: F | E22: 0 | F22: F | G22: F | H22: 1 | I22: F | J22: 0 | K22: 1 | L22: 0 | M22: F | N22: F
B23: Katherine Llantoy | C23: Enero | D23: F | E23: 0 | F23: F | G23: F | H23: 0 | I23: F | J23: 1 | K23: 1 | L23: 0 | M23: F | N23: F
B24: Manuel Alejandro Cabana | C24: Enero | D24: F | E24: 1 | F24: F | G24: F | H24: V | I24: F | J24: 1 | K24: 0 | L24: 0 | M24: F | N24: F
B25: TOTAL | E25: =SUM(E16:E24) -> 2 | H25: =SUM(H16:H24) -> 2 | J25: =SUM(J16:J24) -> 3 | K25: =SUM(K16:K24) -> 3 | L25: =SUM(L16:L24) -> 3
C28: 1 | D28: Oficina
C29: 0 | D29: Teletrabajo

Sheet Hoja2
A1: 45717
A2: 45718
A3: 45719
A4: 45720
A5: 45721
A6: 45722
A7: 45723
A8: 45724
A9: 45725
A10: 45726
A11: 45727
A12: 45728
... A31: 45747

Sheet Intervenciones NyM
A1: Mes | B1: Día | C1: Fecha | D1: Técnico | E1: Grupo | F1: Hora Incio | G1: Hora Fin | H1: Duración | I1: Id Cambio | J1: Nombre cambio | K1: Observaciones / Resultados
A2: Enero | B2: Miércoles | C2: 45292 | D2: FREEZE NAVIDAD
A3: Enero | B3: Jueves | C3: 45293 | D3: FREEZE NAVIDAD
A4: Enero | B4: Viernes | C4: 45294 | D4: FREEZE NAVIDAD
A5: Enero | B5: Sábado | C5: 45295 | D5: FREEZE NAVIDAD
A6: Enero | B6: Domingo | C6: 45296 | D6: FREEZE NAVIDAD
A7: Enero | B7: Lunes | C7: 45297 | D7: FREEZE NAVIDAD
A8: Enero | B8: Martes | C8: 45298 | D8: FREEZE NAVIDAD
A9: Enero | B9: Miércoles | C9: 45299 | D9: FREEZE NAVIDAD
A10: Enero | B10: Jueves | C10: 45300 | D10: FREEZE NAVIDAD
A11: Enero | B11: Viernes | C11: 45301 | D11: FREEZE NAVIDAD
A12: Enero | B12: Sábado | C12: 45668
A13: Enero | B13: Domingo | C13: 45669
A14: Enero | B14: Lunes | C14: 44209
A15: Enero | B15: Martes | C15: 45305
A16: Enero | B16: Miércoles | C16: 45306
A17: Enero | B17: Jueves | C17: 45307
A18: Enero | B18: Viernes | C18: 45308
A19: Enero | B19: Sábado | C19: 45309
A20: Enero | B20: Domingo | C20: 45310 | D20: Francisco Javier Puertas de la Plaza | E20: Voice | F20: 0.041666667 | G20: 0.14236111 | H20: 0.10069444 | I20: CHG001999260 | J20: Upgrade in place Redhat de las máquinas de Base de datos por obsolescencia. DB de EurekaVR STP ES - Cadena 2 | K20: OK
A21: Enero | B21: Lunes | C21: 45311
A22: Enero | B22: Martes | C22: 45312
A23: Enero | B23: Miércoles | C23: 45313
A24: Enero | B24: Jueves | C24: 45345
A25: Enero | B25: Viernes | C25: 45315 | D25: Alfonso Gómez Calzado | E25: Voice | F25: 0.91666667 | G25: 0.065972222 | H25: 0.14930556 | I25: CHG002007196 | J25: Vuelta a configuración 50%-50% en el registro de teléfonos HCS sobre los DCs de Telefónica tras fin de incidencia y fin de freeze navideño | K25: OK
A26: Enero | B26: Viernes | C26: 45315 | D26: Rebeca Ayarza Nebreda | E26: Multimedia | F26: 0.95833333 | G26: 0.97986111 | H26: 0.020833333 | I26: CHG002010640 | J26: Sustitución de certificado del dominio waveplayer01.santandergroup.net | K26: OK
A27: Enero | B27: Sábado | C27: 45316 | D27: Alfonso Gómez Calzado | E27: Voice | F27: 0.33333333 | G27: 0.61805556 | H27: 0.28472222 | I27: CHG002009913 | J27: Plan de Migración de telefonía corporativa Cisco HCS a Cisco Webex Calling - Cambio 1 de 12 | K27: OK
A28: Enero | B28: Domingo | C28: 45317
A29: Enero | B29: Lunes | C29: 45318
A30: Enero | B30: Martes | C30: 45319
A31: Enero | B31: Miércoles | C31: 45320
A32: Enero | B32: Jueves | C32: 45321
A33: Enero | B33: Viernes | C33: 45322
A35: Febrero | B35: Sábado | C35: 45689
A36: Febrero | B36: Domingo | C36: 45690
A37: Febrero | B37: Lunes | C37: 45691
A38: Febrero | B38: Martes | C38: 45692
A39: Febrero | B39: Miércoles | C39: 45693
A40: Febrero | B40: Jueves | C40: 45694 | D40: Alfonso Gómez Calzado | E40: Voice | F40: 0.83333333 | G40: 0.95833333 | H40: 0.125 | I40: CHG002031665 | J40: Reconfigurar Data Policy para enrutar los servidores de Webex calling por red interna en lugar de internet breakout - Edificios Alhambra y Mauricio Legendre | K40: OK
A41: Febrero | B41: Jueves | C41: 45694 | D41: Jose María Moreno Moreno | E41: Voice | F41: 0.95833333 | G41: 0.020833333 | H41: 0.0625 | I41: CHG002038945 | J41: Renovación de certificado en servidor centralita standby del Call Center STP España | K41: OK
...

Sheet Cuadrante Móvil Guardia Network
A1: posición | B1: técnicos | C1: teléfono
A2: 1 | B2: Fernando Manuel Langreo Gonzalez | C2: 652804917
A3: 2 | B3: Jose Miguel Perea Conde | C3: 684432273
A4: 3 | B4: Luis Fariñas Moreno | C4: 658369172
A5: 4 | B5: Carlos Bourgeon Perez | C5: 605486183
A6: 5 | B6: Ricardo Ortiz Merino | C6: 684433715
A7: 6 | B7: Eduardo Rodriguez Izquierdo | C7: 684433775
A8: 7 | B8: Jorge Zamorano Rueda | C8: 605486537
A9: 8 | B9: Servicio BT Guardia 24x7 | C9: 651577705

Sheet TURNOS TELETRABAJO NETWORK
A1: NOMBRE | B1: DEPARTAMENTO | C1: ROL | D1: LUNES | E1: MARTES | F1: MIERCOLES | G1: JUEVES | H1: VIERNES | I1: DIAS OFICINA | J1: TRABAJO OFICINA
A2: Katherine Llantoy Salvatierra | B2: Network | C2: INTERNO | D2: 1 | E2: 1 | F2: 0.5 | G2: 0 | H2: 0 | I2: =SUM(D2:H2) -> 2.5 | J2: =SUM(D2:H2)/5 -> 0.5
A3: Eduardo Rodriguez Izquierdo | B3: Network | C3: INTERNO | D3: 0 | E3: 1 | F3: 1 | G3: 0 | H3: 0.5 | I3: =SUM(D3:H3) -> 2.5 | J3: =SUM(D3:H3)/5 -> 0.5
A4: Jorge Zamorano Rueda | B4: Network | C4: INTERNO | D4: 0 | E4: 1 | F4: 0 | G4: 1 | H4: 0.5 | I4: =SUM(D4:H4) -> 2.5 | J4: =SUM(D4:H4)/5 -> 0.5
A5: DANIEL PORTUGUES MONCALVILLO | B5: Network | C5: INTERNO | D5: 1 | E5: 0 | F5: 0.5 | G5: 0 | H5: 1 | I5: =SUM(D5:H5) -> 2.5 | J5: =SUM(D5:H5)/5 -> 0.5
A6: FERNANDO MIGUEL LOURIDO DOÑORO | B6: Network | C6: INTERNO | D6: 0 | E6: 0 | F6: 1 | G6: 1 | H6: 0.5 | I6: =SUM(D6:H6) -> 2.5 | J6: =SUM(D6:H6)/5 -> 0.5
A7: JOSE MARIA ANDRES BECERRA | B7: Network | C7: INTERNO | D7: 0 | E7: 0 | F7: 1 | G7: 1 | H7: 0.5 | I7: =SUM(D7:H7) -> 2.5 | J7: =SUM(D7:H7)/5 -> 0.5
A8: ISRAEL HURTADO ARRIBAS | B8: Network | C8: INTERNO | D8: 1 | E8: 1 | F8: 1 | G8: 0 | H8: 0 | I8: =SUM(D8:H8) -> 3 | J8: 0.5
A9: MANUEL CABANA ROBAINA | B9: Network | C9: INTERNO | D9: 0 | E9: 0.5 | F9: 0 | G9: 1 | H9: 1 | I9: =SUM(D9:H9) -> 2.5 | J9: =SUM(D9:H9)/5 -> 0.5
A10: FRANCISCO JAVIER PASTOR | B10: Network | C10: INTERNO | D10: 1 | E10: 0 | F10: 1 | G10: 0 | H10: 1 | I10: =SUM(D10:H10) -> 3 | J10: 0.5
A11: FRANCISCO JAVIER GARCIA MATA | B11: Network | C11: INTERNO | D11: 0 | E11: 0 | F11: 1 | G11: 1 | H11: 0 | I11: =SUM(D11:H11) -> 2 | J11: 0.5
A12: ROBERTO PADOVANO GONZALEZ | B12: Network | C12: INTERNO | D12: 0 | E12: 1 | F12: 0 | G12: 0.5 | H12: 1 | I12: =SUM(D12:H12) -> 2.5
A13: TOTAL | D13: =SUM(D2:D12) -> 4 | E13: =SUM(E2:E12) -> 5.5 | F13: =SUM(F2:F12) -> 7 | G13: =SUM(G2:G12) -> 5.5 | H13: =SUM(H2:H12) -> 6 | I13: =SUM(I2:I12) -> 28 | J13: 0.5
A16: SEMANA IMPAR (1-7, 15-22)
A18: PERSONA | B18: LUNES | C18: MARTES | D18: MIERCOLES | E18: JUEVES | F18: VIERNES | G18: DIAS OFICINA
A19: Katherine Llantoy Salvatierra | B19: 1 | C19: 1 | D19: 0 | E19: 0 | F19: 0 | G19: =SUM(B19:F19) -> 2 | H19: L, M, X
A20: Eduardo Rodriguez Izquierdo | B20: 0 | C20: 1 | D20: 0 | E20: 1 | F20: 0 | G20: =SUM(B20:F20) -> 2 | H20: M,J
